
2025-08-04 17:07:52,682 - __main__ - ERROR - 配置键缺失: 'et_k_llm' - 文件: setup.yaml
Traceback (most recent call last):
  File "c:\Users\gwf\Documents\doc_chunk\Utils\llm.py", line 15, in get_llm
    type= data["graph_config"][type]
          ~~~~~~~~~~~~~~~~~~~~^^^^^^
KeyError: 'et_k_llm'
2025-08-05 19:13:02,219 - __main__ - ERROR - 第 1 次迭代失败: 'Input to PromptTemplate is missing variables {\'\\n  "modifications"\'}.  Expected: [\'\\n  "modifications"\', \'key_knowledge_trees\', \'source_doc\'] Received: [\'source_doc\', \'key_knowledge_trees\']\nNote: if you intended {\n  "modifications"} to be part of the string and not a variable, please escape it with double curly braces like: \'{{\n  "modifications"}}\'.\nFor troubleshooting, visit: https://python.langchain.com/docs/troubleshooting/errors/INVALID_PROMPT_INPUT '
2025-08-07 14:00:19,683 - __main__ - ERROR - 解析结果时出错: 1 validation error for KnowledgeTree
root.children
  Input should be a valid list [type=list_type, input_value={'chapter1': {'title': '...之日起施行。'}}}}, input_type=dict]
    For further information visit https://errors.pydantic.dev/2.11/v/list_type
2025-08-07 16:12:36,354 - __main__ - ERROR - 解析结果时出错: 1 validation error for KnowledgeTree
summary
  Field required [type=missing, input_value={'metadata': {'total_node...的互联互通'}]}]}}, input_type=dict]
    For further information visit https://errors.pydantic.dev/2.11/v/missing
2025-08-07 16:29:02,755 - __main__ - ERROR - 解析结果时出错: 1 validation error for KnowledgeTree
summary
  Field required [type=missing, input_value={'metadata': {'total_node...单或依据的'}]}]}}, input_type=dict]
    For further information visit https://errors.pydantic.dev/2.11/v/missing
2025-08-07 16:40:54,335 - __main__ - ERROR - 加载setup.yaml配置失败: [Errno 2] No such file or directory: '../setup.yaml' - 文件: ../setup.yaml
Traceback (most recent call last):
  File "c:\Users\gwf\Documents\doc_chunk\get_knowledge\get_k_worker.py", line 20, in init_get_k_chain
    with open(setup_file, encoding='utf-8') as f:
         ^^^^^^^^^^^^^^^^^^^^^^^^^^^^^^^^^^
FileNotFoundError: [Errno 2] No such file or directory: '../setup.yaml'
2025-08-07 16:41:17,481 - __main__ - ERROR - 提示词文件未找到: ../prompt/get_k_prompt.md
2025-08-07 16:41:17,481 - __main__ - ERROR - 加载setup.yaml配置失败: [Errno 2] No such file or directory: '../prompt/get_k_prompt.md' - 文件: setup.yaml
Traceback (most recent call last):
  File "c:\Users\gwf\Documents\doc_chunk\get_knowledge\get_k_worker.py", line 27, in init_get_k_chain
    with open(get_k_prompt_file, encoding='utf-8') as prompt_file:
         ^^^^^^^^^^^^^^^^^^^^^^^^^^^^^^^^^^^^^^^^^
FileNotFoundError: [Errno 2] No such file or directory: '../prompt/get_k_prompt.md'
2025-08-07 16:53:19,813 - __main__ - ERROR - 加载setup.yaml配置失败: [Errno 2] No such file or directory: '../setup.yaml' - 文件: ../setup.yaml
Traceback (most recent call last):
  File "c:\Users\gwf\Documents\doc_chunk\get_knowledge\get_k_worker.py", line 20, in init_get_k_chain
    with open(setup_file, encoding='utf-8') as f:
         ^^^^^^^^^^^^^^^^^^^^^^^^^^^^^^^^^^
FileNotFoundError: [Errno 2] No such file or directory: '../setup.yaml'
2025-08-08 09:23:51,688 - __main__ - ERROR - 解析结果时出错: 1 validation error for KnowledgeTree
children
  Input should be a valid list [type=list_type, input_value={'title': '附则', 'cont...等多个方面。'}}}}}, input_type=dict]
    For further information visit https://errors.pydantic.dev/2.11/v/list_type
2025-08-08 09:26:03,572 - __main__ - ERROR - 解析结果时出错: 1 validation error for KnowledgeTree
children
  Input should be a valid list [type=list_type, input_value={'第一章 总则': {'ti...或者对投诉的'}}}}, input_type=dict]
    For further information visit https://errors.pydantic.dev/2.11/v/list_type
2025-08-08 10:03:53,990 - root - ERROR - setup.yaml配置文件解析错误: mapping values are not allowed here
  in "setup.yaml", line 21, column 13
2025-08-08 10:03:53,990 - __main__ - ERROR - YAML解析失败: mapping values are not allowed here
  in "setup.yaml", line 21, column 13 - 文件: setup.yaml
Traceback (most recent call last):
  File "c:\Users\gwf\Documents\doc_chunk\Utils\llm.py", line 13, in get_llm
    data = yaml.safe_load(f)
           ^^^^^^^^^^^^^^^^^
  File "C:\Users\gwf\Documents\doc_chunk\.venv\Lib\site-packages\yaml\__init__.py", line 125, in safe_load
    return load(stream, SafeLoader)
           ^^^^^^^^^^^^^^^^^^^^^^^^
  File "C:\Users\gwf\Documents\doc_chunk\.venv\Lib\site-packages\yaml\__init__.py", line 81, in load
    return loader.get_single_data()
           ^^^^^^^^^^^^^^^^^^^^^^^^
  File "C:\Users\gwf\Documents\doc_chunk\.venv\Lib\site-packages\yaml\constructor.py", line 49, in get_single_data
    node = self.get_single_node()
           ^^^^^^^^^^^^^^^^^^^^^^
  File "C:\Users\gwf\Documents\doc_chunk\.venv\Lib\site-packages\yaml\composer.py", line 36, in get_single_node
    document = self.compose_document()
               ^^^^^^^^^^^^^^^^^^^^^^^
  File "C:\Users\gwf\Documents\doc_chunk\.venv\Lib\site-packages\yaml\composer.py", line 55, in compose_document
    node = self.compose_node(None, None)
           ^^^^^^^^^^^^^^^^^^^^^^^^^^^^^
  File "C:\Users\gwf\Documents\doc_chunk\.venv\Lib\site-packages\yaml\composer.py", line 84, in compose_node
    node = self.compose_mapping_node(anchor)
           ^^^^^^^^^^^^^^^^^^^^^^^^^^^^^^^^^
  File "C:\Users\gwf\Documents\doc_chunk\.venv\Lib\site-packages\yaml\composer.py", line 127, in compose_mapping_node
    while not self.check_event(MappingEndEvent):
              ^^^^^^^^^^^^^^^^^^^^^^^^^^^^^^^^^
  File "C:\Users\gwf\Documents\doc_chunk\.venv\Lib\site-packages\yaml\parser.py", line 98, in check_event
    self.current_event = self.state()
                         ^^^^^^^^^^^^
  File "C:\Users\gwf\Documents\doc_chunk\.venv\Lib\site-packages\yaml\parser.py", line 428, in parse_block_mapping_key
    if self.check_token(KeyToken):
       ^^^^^^^^^^^^^^^^^^^^^^^^^^
  File "C:\Users\gwf\Documents\doc_chunk\.venv\Lib\site-packages\yaml\scanner.py", line 116, in check_token
    self.fetch_more_tokens()
  File "C:\Users\gwf\Documents\doc_chunk\.venv\Lib\site-packages\yaml\scanner.py", line 223, in fetch_more_tokens
    return self.fetch_value()
           ^^^^^^^^^^^^^^^^^^
  File "C:\Users\gwf\Documents\doc_chunk\.venv\Lib\site-packages\yaml\scanner.py", line 577, in fetch_value
    raise ScannerError(None, None,
yaml.scanner.ScannerError: mapping values are not allowed here
  in "setup.yaml", line 21, column 13
2025-08-08 10:04:50,149 - root - ERROR - setup.yaml配置文件解析错误: while parsing a block mapping
  in "setup.yaml", line 20, column 3
expected <block end>, but found '<scalar>'
  in "setup.yaml", line 24, column 19
2025-08-08 10:04:50,149 - __main__ - ERROR - YAML解析失败: while parsing a block mapping
  in "setup.yaml", line 20, column 3
expected <block end>, but found '<scalar>'
  in "setup.yaml", line 24, column 19 - 文件: setup.yaml
Traceback (most recent call last):
  File "c:\Users\gwf\Documents\doc_chunk\Utils\llm.py", line 13, in get_llm
    data = yaml.safe_load(f)
           ^^^^^^^^^^^^^^^^^
  File "C:\Users\gwf\Documents\doc_chunk\.venv\Lib\site-packages\yaml\__init__.py", line 125, in safe_load
    return load(stream, SafeLoader)
           ^^^^^^^^^^^^^^^^^^^^^^^^
  File "C:\Users\gwf\Documents\doc_chunk\.venv\Lib\site-packages\yaml\__init__.py", line 81, in load
    return loader.get_single_data()
           ^^^^^^^^^^^^^^^^^^^^^^^^
  File "C:\Users\gwf\Documents\doc_chunk\.venv\Lib\site-packages\yaml\constructor.py", line 49, in get_single_data
    node = self.get_single_node()
           ^^^^^^^^^^^^^^^^^^^^^^
  File "C:\Users\gwf\Documents\doc_chunk\.venv\Lib\site-packages\yaml\composer.py", line 36, in get_single_node
    document = self.compose_document()
               ^^^^^^^^^^^^^^^^^^^^^^^
  File "C:\Users\gwf\Documents\doc_chunk\.venv\Lib\site-packages\yaml\composer.py", line 55, in compose_document
    node = self.compose_node(None, None)
           ^^^^^^^^^^^^^^^^^^^^^^^^^^^^^
  File "C:\Users\gwf\Documents\doc_chunk\.venv\Lib\site-packages\yaml\composer.py", line 84, in compose_node
    node = self.compose_mapping_node(anchor)
           ^^^^^^^^^^^^^^^^^^^^^^^^^^^^^^^^^
  File "C:\Users\gwf\Documents\doc_chunk\.venv\Lib\site-packages\yaml\composer.py", line 133, in compose_mapping_node
    item_value = self.compose_node(node, item_key)
                 ^^^^^^^^^^^^^^^^^^^^^^^^^^^^^^^^^
  File "C:\Users\gwf\Documents\doc_chunk\.venv\Lib\site-packages\yaml\composer.py", line 84, in compose_node
    node = self.compose_mapping_node(anchor)
           ^^^^^^^^^^^^^^^^^^^^^^^^^^^^^^^^^
  File "C:\Users\gwf\Documents\doc_chunk\.venv\Lib\site-packages\yaml\composer.py", line 127, in compose_mapping_node
    while not self.check_event(MappingEndEvent):
              ^^^^^^^^^^^^^^^^^^^^^^^^^^^^^^^^^
  File "C:\Users\gwf\Documents\doc_chunk\.venv\Lib\site-packages\yaml\parser.py", line 98, in check_event
    self.current_event = self.state()
                         ^^^^^^^^^^^^
  File "C:\Users\gwf\Documents\doc_chunk\.venv\Lib\site-packages\yaml\parser.py", line 438, in parse_block_mapping_key
    raise ParserError("while parsing a block mapping", self.marks[-1],
yaml.parser.ParserError: while parsing a block mapping
  in "setup.yaml", line 20, column 3
expected <block end>, but found '<scalar>'
  in "setup.yaml", line 24, column 19
2025-08-08 10:13:51,431 - root - ERROR - setup.yaml配置文件解析错误: mapping values are not allowed here
  in "setup.yaml", line 29, column 13
2025-08-08 10:13:51,431 - root - ERROR - setup.yaml配置文件解析错误: mapping values are not allowed here
  in "setup.yaml", line 29, column 13
2025-08-08 10:13:51,431 - root - ERROR - setup.yaml配置文件解析错误: mapping values are not allowed here
  in "setup.yaml", line 29, column 13
2025-08-08 10:13:51,464 - __main__ - ERROR - YAML解析失败: mapping values are not allowed here
  in "setup.yaml", line 29, column 13 - 文件: setup.yaml
Traceback (most recent call last):
  File "c:\Users\gwf\Documents\doc_chunk\get_knowledge\get_k_worker.py", line 21, in init_get_k_chain
    setup_data = yaml.safe_load(f)
                 ^^^^^^^^^^^^^^^^^
  File "C:\Users\gwf\Documents\doc_chunk\.venv\Lib\site-packages\yaml\__init__.py", line 125, in safe_load
    return load(stream, SafeLoader)
           ^^^^^^^^^^^^^^^^^^^^^^^^
  File "C:\Users\gwf\Documents\doc_chunk\.venv\Lib\site-packages\yaml\__init__.py", line 81, in load
    return loader.get_single_data()
           ^^^^^^^^^^^^^^^^^^^^^^^^
  File "C:\Users\gwf\Documents\doc_chunk\.venv\Lib\site-packages\yaml\constructor.py", line 49, in get_single_data
    node = self.get_single_node()
           ^^^^^^^^^^^^^^^^^^^^^^
  File "C:\Users\gwf\Documents\doc_chunk\.venv\Lib\site-packages\yaml\composer.py", line 36, in get_single_node
    document = self.compose_document()
               ^^^^^^^^^^^^^^^^^^^^^^^
  File "C:\Users\gwf\Documents\doc_chunk\.venv\Lib\site-packages\yaml\composer.py", line 55, in compose_document
    node = self.compose_node(None, None)
           ^^^^^^^^^^^^^^^^^^^^^^^^^^^^^
  File "C:\Users\gwf\Documents\doc_chunk\.venv\Lib\site-packages\yaml\composer.py", line 84, in compose_node
    node = self.compose_mapping_node(anchor)
           ^^^^^^^^^^^^^^^^^^^^^^^^^^^^^^^^^
  File "C:\Users\gwf\Documents\doc_chunk\.venv\Lib\site-packages\yaml\composer.py", line 127, in compose_mapping_node
    while not self.check_event(MappingEndEvent):
              ^^^^^^^^^^^^^^^^^^^^^^^^^^^^^^^^^
  File "C:\Users\gwf\Documents\doc_chunk\.venv\Lib\site-packages\yaml\parser.py", line 98, in check_event
    self.current_event = self.state()
                         ^^^^^^^^^^^^
  File "C:\Users\gwf\Documents\doc_chunk\.venv\Lib\site-packages\yaml\parser.py", line 428, in parse_block_mapping_key
    if self.check_token(KeyToken):
       ^^^^^^^^^^^^^^^^^^^^^^^^^^
  File "C:\Users\gwf\Documents\doc_chunk\.venv\Lib\site-packages\yaml\scanner.py", line 116, in check_token
    self.fetch_more_tokens()
  File "C:\Users\gwf\Documents\doc_chunk\.venv\Lib\site-packages\yaml\scanner.py", line 223, in fetch_more_tokens
    return self.fetch_value()
           ^^^^^^^^^^^^^^^^^^
  File "C:\Users\gwf\Documents\doc_chunk\.venv\Lib\site-packages\yaml\scanner.py", line 577, in fetch_value
    raise ScannerError(None, None,
yaml.scanner.ScannerError: mapping values are not allowed here
  in "setup.yaml", line 29, column 13
2025-08-08 10:14:05,381 - root - ERROR - setup.yaml配置文件解析错误: mapping values are not allowed here
  in "setup.yaml", line 29, column 13
2025-08-08 10:14:05,381 - __main__ - ERROR - YAML解析失败: mapping values are not allowed here
  in "setup.yaml", line 29, column 13 - 文件: setup.yaml
Traceback (most recent call last):
  File "c:\Users\gwf\Documents\doc_chunk\Utils\llm.py", line 13, in get_llm
    data = yaml.safe_load(f)
           ^^^^^^^^^^^^^^^^^
  File "C:\Users\gwf\Documents\doc_chunk\.venv\Lib\site-packages\yaml\__init__.py", line 125, in safe_load
    return load(stream, SafeLoader)
           ^^^^^^^^^^^^^^^^^^^^^^^^
  File "C:\Users\gwf\Documents\doc_chunk\.venv\Lib\site-packages\yaml\__init__.py", line 81, in load
    return loader.get_single_data()
           ^^^^^^^^^^^^^^^^^^^^^^^^
  File "C:\Users\gwf\Documents\doc_chunk\.venv\Lib\site-packages\yaml\constructor.py", line 49, in get_single_data
    node = self.get_single_node()
           ^^^^^^^^^^^^^^^^^^^^^^
  File "C:\Users\gwf\Documents\doc_chunk\.venv\Lib\site-packages\yaml\composer.py", line 36, in get_single_node
    document = self.compose_document()
               ^^^^^^^^^^^^^^^^^^^^^^^
  File "C:\Users\gwf\Documents\doc_chunk\.venv\Lib\site-packages\yaml\composer.py", line 55, in compose_document
    node = self.compose_node(None, None)
           ^^^^^^^^^^^^^^^^^^^^^^^^^^^^^
  File "C:\Users\gwf\Documents\doc_chunk\.venv\Lib\site-packages\yaml\composer.py", line 84, in compose_node
    node = self.compose_mapping_node(anchor)
           ^^^^^^^^^^^^^^^^^^^^^^^^^^^^^^^^^
  File "C:\Users\gwf\Documents\doc_chunk\.venv\Lib\site-packages\yaml\composer.py", line 127, in compose_mapping_node
    while not self.check_event(MappingEndEvent):
              ^^^^^^^^^^^^^^^^^^^^^^^^^^^^^^^^^
  File "C:\Users\gwf\Documents\doc_chunk\.venv\Lib\site-packages\yaml\parser.py", line 98, in check_event
    self.current_event = self.state()
                         ^^^^^^^^^^^^
  File "C:\Users\gwf\Documents\doc_chunk\.venv\Lib\site-packages\yaml\parser.py", line 428, in parse_block_mapping_key
    if self.check_token(KeyToken):
       ^^^^^^^^^^^^^^^^^^^^^^^^^^
  File "C:\Users\gwf\Documents\doc_chunk\.venv\Lib\site-packages\yaml\scanner.py", line 116, in check_token
    self.fetch_more_tokens()
  File "C:\Users\gwf\Documents\doc_chunk\.venv\Lib\site-packages\yaml\scanner.py", line 223, in fetch_more_tokens
    return self.fetch_value()
           ^^^^^^^^^^^^^^^^^^
  File "C:\Users\gwf\Documents\doc_chunk\.venv\Lib\site-packages\yaml\scanner.py", line 577, in fetch_value
    raise ScannerError(None, None,
yaml.scanner.ScannerError: mapping values are not allowed here
  in "setup.yaml", line 29, column 13
2025-08-08 13:42:59,179 - root - ERROR - setup.yaml配置文件解析错误: mapping values are not allowed here
  in "setup.yaml", line 36, column 13
2025-08-08 13:42:59,179 - root - ERROR - setup.yaml配置文件解析错误: mapping values are not allowed here
  in "setup.yaml", line 36, column 13
2025-08-08 13:42:59,212 - root - ERROR - setup.yaml配置文件解析错误: mapping values are not allowed here
  in "setup.yaml", line 36, column 13
2025-08-08 13:42:59,268 - __main__ - ERROR - 加载setup.yaml配置失败: mapping values are not allowed here
  in "setup.yaml", line 36, column 13
Traceback (most recent call last):
  File "c:\Users\gwf\Documents\doc_chunk\get_knowledge\eva_Omission_k_worker.py", line 107, in init_evaluation_chain
    setup_config = yaml.safe_load(f)
                   ^^^^^^^^^^^^^^^^^
  File "C:\Users\gwf\Documents\doc_chunk\.venv\Lib\site-packages\yaml\__init__.py", line 125, in safe_load
    return load(stream, SafeLoader)
           ^^^^^^^^^^^^^^^^^^^^^^^^
  File "C:\Users\gwf\Documents\doc_chunk\.venv\Lib\site-packages\yaml\__init__.py", line 81, in load
    return loader.get_single_data()
           ^^^^^^^^^^^^^^^^^^^^^^^^
  File "C:\Users\gwf\Documents\doc_chunk\.venv\Lib\site-packages\yaml\constructor.py", line 49, in get_single_data
    node = self.get_single_node()
           ^^^^^^^^^^^^^^^^^^^^^^
  File "C:\Users\gwf\Documents\doc_chunk\.venv\Lib\site-packages\yaml\composer.py", line 36, in get_single_node
    document = self.compose_document()
               ^^^^^^^^^^^^^^^^^^^^^^^
  File "C:\Users\gwf\Documents\doc_chunk\.venv\Lib\site-packages\yaml\composer.py", line 55, in compose_document
    node = self.compose_node(None, None)
           ^^^^^^^^^^^^^^^^^^^^^^^^^^^^^
  File "C:\Users\gwf\Documents\doc_chunk\.venv\Lib\site-packages\yaml\composer.py", line 84, in compose_node
    node = self.compose_mapping_node(anchor)
           ^^^^^^^^^^^^^^^^^^^^^^^^^^^^^^^^^
  File "C:\Users\gwf\Documents\doc_chunk\.venv\Lib\site-packages\yaml\composer.py", line 127, in compose_mapping_node
    while not self.check_event(MappingEndEvent):
              ^^^^^^^^^^^^^^^^^^^^^^^^^^^^^^^^^
  File "C:\Users\gwf\Documents\doc_chunk\.venv\Lib\site-packages\yaml\parser.py", line 98, in check_event
    self.current_event = self.state()
                         ^^^^^^^^^^^^
  File "C:\Users\gwf\Documents\doc_chunk\.venv\Lib\site-packages\yaml\parser.py", line 428, in parse_block_mapping_key
    if self.check_token(KeyToken):
       ^^^^^^^^^^^^^^^^^^^^^^^^^^
  File "C:\Users\gwf\Documents\doc_chunk\.venv\Lib\site-packages\yaml\scanner.py", line 116, in check_token
    self.fetch_more_tokens()
  File "C:\Users\gwf\Documents\doc_chunk\.venv\Lib\site-packages\yaml\scanner.py", line 223, in fetch_more_tokens
    return self.fetch_value()
           ^^^^^^^^^^^^^^^^^^
  File "C:\Users\gwf\Documents\doc_chunk\.venv\Lib\site-packages\yaml\scanner.py", line 577, in fetch_value
    raise ScannerError(None, None,
yaml.scanner.ScannerError: mapping values are not allowed here
  in "setup.yaml", line 36, column 13
2025-08-08 16:17:49,710 - __main__ - ERROR - 添加知识点失败: 无效路径: ['电信市场', '电信业务许可', '基础电信业务', '申请经营基础电信业务']
2025-08-08 16:17:49,716 - __main__ - ERROR - 添加知识点失败: 无效路径: ['电信市场', '电信业务许可', '增值电信业务', '业务范围与许可']
2025-08-08 16:17:49,718 - __main__ - ERROR - 添加知识点失败: 路径节点不存在: 电信市场 -> 电信业务许可 -> 备案新业务
2025-08-08 16:17:49,719 - __main__ - ERROR - 添加知识点失败: 无效路径: ['电信服务', '用户权益', '违约金标准']
2025-08-08 16:17:49,720 - __main__ - ERROR - 添加知识点失败: 无效路径: ['电信服务', '用户权益', '暂停服务']
2025-08-08 16:17:49,722 - __main__ - ERROR - 添加知识点失败: 路径节点不存在: 电信服务 -> 公益服务
2025-08-08 16:17:49,722 - __main__ - ERROR - 添加知识点失败: 路径节点不存在: 电信服务 -> 接入服务
2025-08-08 16:17:49,723 - __main__ - ERROR - 添加知识点失败: 路径节点不存在: 电信建设 -> 电信设备进网
2025-08-08 16:17:49,723 - __main__ - ERROR - 添加知识点失败: 无效路径: ['电信安全', '网络安全', '公共通信保障']
2025-08-08 16:17:49,724 - __main__ - ERROR - 添加知识点失败: 路径节点不存在: 电信安全 -> 电信保障
2025-08-08 16:17:49,726 - __main__ - ERROR - 添加知识点失败: 无效路径: ['电信安全', '网络安全', '内容责任']
2025-08-08 16:17:49,726 - __main__ - ERROR - 添加知识点失败: 无效路径: ['电信安全', '国际通信', '规定']
2025-08-08 16:17:49,727 - __main__ - ERROR - 添加知识点失败: 路径节点不存在: 电信安全 -> 用户通信秘密
2025-08-08 16:17:49,727 - __main__ - ERROR - 添加知识点失败: 无效路径: ['罚则', '经营违规', '禁止竞争']
2025-08-08 16:17:49,727 - __main__ - ERROR - 添加知识点失败: 路径节点不存在: 电信服务 -> 普遍服务义务
2025-08-08 16:17:49,728 - __main__ - ERROR - 添加知识点失败: 路径节点不存在: 罚则 -> 执法处罚
2025-08-08 16:39:36,359 - __main__ - ERROR - 添加知识点失败: 路径节点不存在: 中华人民共和国电信条例
2025-08-08 16:42:19,690 - __main__ - ERROR - 添加知识点失败: 路径节点不存在: 中华人民共和国电信条例
2025-08-08 17:05:25,996 - __main__ - ERROR - 添加知识点失败: 路径节点不存在: 中华人民共和国电信条例
2025-08-08 21:07:26,717 - __main__ - ERROR - 加载文件失败: 2 validation errors for KnowledgeTree
title
  Field required [type=missing, input_value={'knowledge_trees': {'tit...'', 'chunk_results': []}, input_type=dict]
    For further information visit https://errors.pydantic.dev/2.11/v/missing
content
  Field required [type=missing, input_value={'knowledge_trees': {'tit...'', 'chunk_results': []}, input_type=dict]
    For further information visit https://errors.pydantic.dev/2.11/v/missing
Traceback (most recent call last):
  File "c:\Users\gwf\Documents\doc_chunk\get_knowledge\gen_k_chunk_worker.py", line 96, in <module>
    knowledge_trees = KnowledgeTree.model_validate(yaml.safe_load(f))
                      ^^^^^^^^^^^^^^^^^^^^^^^^^^^^^^^^^^^^^^^^^^^^^^^
  File "C:\Users\gwf\Documents\doc_chunk\.venv\Lib\site-packages\pydantic\main.py", line 705, in model_validate
    return cls.__pydantic_validator__.validate_python(
           ^^^^^^^^^^^^^^^^^^^^^^^^^^^^^^^^^^^^^^^^^^^
pydantic_core._pydantic_core.ValidationError: 2 validation errors for KnowledgeTree
title
  Field required [type=missing, input_value={'knowledge_trees': {'tit...'', 'chunk_results': []}, input_type=dict]
    For further information visit https://errors.pydantic.dev/2.11/v/missing
content
  Field required [type=missing, input_value={'knowledge_trees': {'tit...'', 'chunk_results': []}, input_type=dict]
    For further information visit https://errors.pydantic.dev/2.11/v/missing
